<?xml version="1.0" ?>
<robot name="dummy" xmlns:xacro="http://ros.org/wiki/xacro">
  <material name="metal_grey">
    <color rgba="0.5 0.5 0.5 1"/>
  </material>   
    <material name="black">
    <color rgba="0.1 0.1 0.1 1"/>
  </material>   
    <material name="white_grey">
    <color rgba="0.9 0.9 0.9 1"/>
  </material>   
  
	<link name="world"/>

  <link name="base_link">
    <visual>
      <origin rpy="1.5708 0 1.5708" xyz="0 0 0"/>
      <geometry>
        <mesh filename="meshes/body.stl" scale="0.001 0.001 0.001"/>
      </geometry>
      <material name="metal_grey"/>
    </visual>
    <collision>
      <origin rpy="0 0 0" xyz="0 0 0"/>
      <geometry>
        <cylinder length="0.075" radius="0.102"/>
      </geometry>
    </collision>
    <inertial>
      <origin rpy="0 0 0" xyz="0 0 0"/>
      <mass value="1.59306955"/>
      <inertia ixx="+0.00572623" ixy="+0.00000251" ixz="-0.00011380" iyy="+0.00558959" iyz="-0.00000014" izz="+0.00966674"/>
    </inertial>
  </link>
  
  <link name="right1_link">
    <visual>
      <origin rpy="1.5708 0 1.5708" xyz="0 0 0"/>
      <geometry>
        <mesh filename="meshes/leg1.stl" scale="0.001 0.001 0.001"/>
      </geometry>
      <material name="white_grey"/>
    </visual>
    <collision>
      <origin rpy="1.5708 0 1.5708" xyz="0 0 0"/>
      <geometry>
        <mesh filename="meshes/leg1.stl" scale="0.001 0.001 0.001"/>
      </geometry>

    </collision>

    <inertial>
      <origin rpy="0 0 0" xyz="0 0 0"/>
      <mass value="10.0"/>
      <inertia ixx="+0.15418559" ixy="-0.00000235" ixz="+0.00001739" iyy="+0.12937017" iyz="-0.04854267" izz="+0.05964415"/>
    </inertial>
  </link>  
   <link name="left1_link">
    <visual>
      <origin rpy="1.5708 0 1.5708" xyz="0 0 0"/>
      <geometry>
        <mesh filename="meshes/leg1.stl" scale="0.001 0.001 0.001"/>
      </geometry>
      <material name="white_grey"/>
    </visual>
    <collision>
      <origin rpy="1.5708 0 1.5708" xyz="0 0 0"/>
      <geometry>
        <mesh filename="meshes/leg1.stl" scale="0.001 0.001 0.001"/>
      </geometry>

    </collision>

    <inertial>
      <origin rpy="0 0 0" xyz="0 0 0"/>
      <mass value="10.0"/>
      <inertia ixx="+0.15418559" ixy="-0.00000235" ixz="+0.00001739" iyy="+0.12937017" iyz="-0.04854267" izz="+0.05964415"/>
    </inertial>
  </link>   



   <link name="left2_link">
    <visual>
      <origin rpy="1.5708 0 1.5708" xyz="0 0 0"/>
      <geometry>
        <mesh filename="meshes/leg2.stl" scale="0.001 0.001 0.001"/>
      </geometry>
      <material name="white_grey"/>
    </visual>
    <collision>
      <origin rpy="1.5708 0 1.5708" xyz="0 0 0"/>
      <geometry>
        <mesh filename="meshes/leg2.stl" scale="0.001 0.001 0.001"/>
      </geometry>

    </collision>

    <inertial>
      <origin rpy="0 0 0" xyz="0 0 0"/>
      <mass value="10.0"/>
      <inertia ixx="+0.15418559" ixy="-0.00000235" ixz="+0.00001739" iyy="+0.12937017" iyz="-0.04854267" izz="+0.05964415"/>
    </inertial>
  </link>   

  
   <link name="right2_link">
    <visual>
      <origin rpy="1.5708 0 1.5708" xyz="0 0 0"/>
      <geometry>
        <mesh filename="meshes/leg2.stl" scale="0.001 0.001 0.001"/>
      </geometry>
      <material name="white_grey"/>
    </visual>
    <collision>
      <origin rpy="1.5708 0 1.5708" xyz="0 0 0"/>
      <geometry>
        <mesh filename="meshes/leg2.stl" scale="0.001 0.001 0.001"/>
      </geometry>

    </collision>

    <inertial>
      <origin rpy="0 0 0" xyz="0 0 0"/>
      <mass value="10.0"/>
      <inertia ixx="+0.15418559" ixy="-0.00000235" ixz="+0.00001739" iyy="+0.12937017" iyz="-0.04854267" izz="+0.05964415"/>
    </inertial>
  </link>   
  
  <joint name="world_to_base" type="fixed">
    <parent link="world"/>
    <child link="base_link"/>
    <origin rpy="0 0 0" xyz="0 0 1"/>
  </joint>
  
  
  <joint name="right0" type="revolute">
    <parent link="base_link"/>
    <child link="right1_link"/>
    <origin rpy="0 0 0" xyz="0 -0.095 -0.266"/>
    <axis xyz="0 1 0"/>
    <limit effort="10" lower="-3.05432619099" upper="3.05432619099" velocity="1"/>
  </joint>  
  
  <joint name="left0" type="revolute">
    <parent link="base_link"/>
    <child link="left1_link"/>
    <origin rpy="0 0 0" xyz="0 0.095 -0.266"/>
    <axis xyz="0 1 0"/>
    <limit effort="10" lower="-3.05432619099" upper="3.05432619099" velocity="1"/>
  </joint>    
  
  <joint name="left1" type="revolute">
    <parent link="left1_link"/>
    <child link="left2_link"/>
    <origin rpy="0 0 0" xyz="0 0.00 -0.355"/>
    <axis xyz="0 1 0"/>
    <limit effort="10" lower="-3.05432619099" upper="3.05432619099" velocity="1"/>
  </joint>     
  
  <joint name="right1" type="revolute">
    <parent link="right1_link"/>
    <child link="right2_link"/>
    <origin rpy="0 0 0" xyz="0 0.00 -0.355"/>
    <axis xyz="0 1 0"/>
    <limit effort="10" lower="-3.05432619099" upper="3.05432619099" velocity="1"/>
  </joint>        
</robot>
